Workbook

Sheet Sheet2
A1: Customer_ID | B1: Customer_Name | C1: Region | D1: Product_Category | E1: Sales | F1: Quantity | G1: Discount | H1: Order_Date | I1: Profit | J1: Timestamp
A2: CUST016 | B2: David Thomas | C2: South | D2: Clothing | E2: 928.32 | F2: 2 | G2: 0.05 | H2: 45754 | I2: 440.95
A3: CUST028 | B3: Robert Anderson | C3: South | D3: Office Supplies | E3: 740.8 | F3: 3 | G3: 0 | H3: 45749 | I3: 333.36
A4: CUST007 | B4: James Davis | C4: South | D4: Clothing | E4: 762.14 | F4: 9 | G4: 0 | H4: 45743 | I4: 381.07
A5: CUST005 | B5: Robert Anderson | C5: South | D5: Electronics | E5: 760.93 | F5: 4 | G5: 0.15 | H5: 45396 | I5: 161.7
A6: CUST009 | B6: Michael Anderson | C6: South | D6: Furniture | E6: 1184.25 | F6: 11 | G6: 0.2 | H6: 45742 | I6: 331.59
A7: CUST023 | B7: Mary Wilson | C7: South | D7: Clothing | E7: 682.24 | F7: 1 | G7: 0 | H7: 45738 | I7: 341.12
A8: CUST009 | B8: Linda Taylor | C8: South | D8: Clothing | E8: 689.43 | F8: 9 | G8: 0.1 | H8: 45736 | I8: 310.24
A9: CUST014 | B9: Emma Davis | C9: South | D9: Books | E9: 1064.19 | F9: 18 | G9: 0.05 | H9: 45725 | I9: 404.39
A10: CUST003 | B10: Sarah Anderson | C10: South | D10: Books | E10: 704.28 | F10: 15 | G10: 0.2 | H10: 45712 | I10: 225.37
A11: CUST004 | B11: Mary Davis | C11: South | D11: Office Supplies | E11: 573.32 | F11: 19 | G11: 0.1 | H11: 45703 | I11: 232.19
A12: CUST023 | B12: James Taylor | C12: South | D12: Clothing | E12: 1118.34 | F12: 6 | G12: 0.2 | H12: 45674 | I12: 447.34
A13: CUST015 | B13: Robert Anderson | C13: South | D13: Furniture | E13: 1054.56 | F13: 11 | G13: 0.1 | H13: 45669 | I13: 332.19
... A43: CUST008 | B43: John Brown | C43: South | D43: Electronics | E43: 775.45 | F43: 6 | G43: 0.1 | H43: 45457 | I43: 174.48

Sheet Analysis
A1: Conditional Formatting for Top 10 Item in customer_id | D1: WHAT IF Analysis | G1: Linear Regression | J1: Linear Regression Output for Profit vs Sales | V1: Data Storytelling — Sales vs Profit Chart | Y1: Up/Down Arrows IN Monthly Sales Growth | AC1: Find High-Value Customers using INDEX, MATCH and FILTER
A2: Customer_ID | B2: Total Purchase | D2: Scenario | E2: Value | G2: Profit | H2: Sales | V2: Sales | W2: Profit | Y2: Month | Z2: Total Sales | AA2: Sales Growth | AC2: Customer Name | AD2: Total Sales | AF2: INDEX | AG2: LARGE
A3: CUST019 | B3: =SUMIF(Sales_Data!$A$2:$A$201,A3,Sales_Data!$E$2:$E$201) -> 4640.11 | D3: Sales | E3: 1036.09 | G3: 331.55 | H3: 1036.09 | J3: SUMMARY OUTPUT | V3: =Sales_Data!E2 -> 1036.09 | W3: =Sales_Data!I2 -> 331.55 | Y3: =DATE(YEAR(MIN(Sales_Data!H6:H205)),MONTH(MIN(Sales_Data!H6:H205)),1) -> 45383 | Z3: =SUMIFS(Sales_Data!$E$2:$E$201,Sales_Data!$H$2:$H$201,">="&Y3,Sales_Data!$H$2:$H$201,"<"&EDATE(Y3,1)) -> 19029.96 | AA3: =IFERROR((Z3-Z2)/Z2,0) -> 0 | AC3: {=_xlfn.UNIQUE(Sales_Data!B2:B201)} -> James Davis | AD3: =SUMIF(Sales_Data!$B$2:$B$201,AC2,Sales_Data!$E$2:$E$201) -> 0 | AF3: =INDEX($A$3:$A$29,MATCH(LARGE($B$3:$B$29,ROWS($1:1)),$B$3:$B$29,0)) -> CUST007 | AG3: =LARGE($B$3:$B$29,ROWS($1:1)) -> 9941.88
A4: CUST012 | B4: =SUMIF(Sales_Data!$A$2:$A$201,A4,Sales_Data!$E$2:$E$201) -> 8339 | D4: Original Discount | E4: 0.2 | G4: 440.51 | H4: 1101.28 | V4: =Sales_Data!E3 -> 1101.28 | W4: =Sales_Data!I3 -> 440.51 | Y4: =EDATE(Y3,1) -> 45413 | Z4: =SUMIFS(Sales_Data!$E$2:$E$201,Sales_Data!$H$2:$H$201,">="&Y4,Sales_Data!$H$2:$H$201,"<"&EDATE(Y4,1)) -> 18507.34 | AA4: =IFERROR((Z4-Z3)/Z3,0) -> -0.027463011 | AC4: Robert Anderson | AD4: =SUMIF(Sales_Data!$B$2:$B$201,AC3,Sales_Data!$E$2:$E$201) -> 6255.7
A5: CUST017 | B5: =SUMIF(Sales_Data!$A$2:$A$201,A5,Sales_Data!$E$2:$E$201) -> 3419.2 | D5: New Discount | E5: 0.1 | G5: 285.34 | H5: 713.34 | J5: Regression Statistics | V5: =Sales_Data!E4 -> 713.34 | W5: =Sales_Data!I4 -> 285.34 | Y5: =EDATE(Y4,1) -> 45444 | Z5: =SUMIFS(Sales_Data!$E$2:$E$201,Sales_Data!$H$2:$H$201,">="&Y5,Sales_Data!$H$2:$H$201,"<"&EDATE(Y5,1)) -> 20187.51 | AA5: =IFERROR((Z5-Z4)/Z4,0) -> 0.090783981 | AC5: James Taylor | AD5: =SUMIF(Sales_Data!$B$2:$B$201,AC4,Sales_Data!$E$2:$E$201) -> 8331.85 | AF5: FILTER
A6: CUST005 | B6: =SUMIF(Sales_Data!$A$2:$A$201,A6,Sales_Data!$E$2:$E$201) -> 6666.13 | D6: Original Profit | E6: 331.55 | G6: 161.7 | H6: 760.93 | J6: Multiple R | K6: 0.77340306 | V6: =Sales_Data!E5 -> 760.93 | W6: =Sales_Data!I5 -> 161.7 | Y6: =EDATE(Y5,1) -> 45474 | Z6: =SUMIFS(Sales_Data!$E$2:$E$201,Sales_Data!$H$2:$H$201,">="&Y6,Sales_Data!$H$2:$H$201,"<"&EDATE(Y6,1)) -> 11609.04 | AA6: =IFERROR((Z6-Z5)/Z5,0) -> -0.42493948 | AC6: James Wilson | AD6: =SUMIF(Sales_Data!$B$2:$B$201,AC5,Sales_Data!$E$2:$E$201) -> 5615.28 | AF6: {=_xlfn._xlws.FILTER(A3:B29,B3:B29>8000,"No Customers Found")} -> CUST012 | AG6: 8339
A7: CUST030 | B7: =SUMIF(Sales_Data!$A$2:$A$201,A7,Sales_Data!$E$2:$E$201) -> 7928.71 | D7: Estimated New Profit | E7: =E6+(E4-E5)*E3 -> 435.159 | G7: 271.04 | H7: 847 | J7: R Square | K7: 0.5981523 | V7: =Sales_Data!E6 -> 847 | W7: =Sales_Data!I6 -> 271.04 | Y7: =EDATE(Y6,1) -> 45505 | Z7: =SUMIFS(Sales_Data!$E$2:$E$201,Sales_Data!$H$2:$H$201,">="&Y7,Sales_Data!$H$2:$H$201,"<"&EDATE(Y7,1)) -> 10091.7 | AA7: =IFERROR((Z7-Z6)/Z6,0) -> -0.13070331 | AC7: Michael Anderson | AD7: =SUMIF(Sales_Data!$B$2:$B$201,AC6,Sales_Data!$E$2:$E$201) -> 20774.74 | AF7: CUST007 | AG7: 9941.88
A8: CUST007 | B8: =SUMIF(Sales_Data!$A$2:$A$201,A8,Sales_Data!$E$2:$E$201) -> 9941.88 | G8: 304.18 | H8: 965.64 | J8: Adjusted R Square | K8: 0.59612277 | V8: =Sales_Data!E7 -> 965.64 | W8: =Sales_Data!I7 -> 304.18 | Y8: =EDATE(Y7,1) -> 45536 | Z8: =SUMIFS(Sales_Data!$E$2:$E$201,Sales_Data!$H$2:$H$201,">="&Y8,Sales_Data!$H$2:$H$201,"<"&EDATE(Y8,1)) -> 20533.5 | AA8: =IFERROR((Z8-Z7)/Z7,0) -> 1.0346919 | AC8: Linda Wilson | AD8: =SUMIF(Sales_Data!$B$2:$B$201,AC7,Sales_Data!$E$2:$E$201) -> 7881.9 | AF8: CUST026 | AG8: 9371.81
A9: CUST001 | B9: =SUMIF(Sales_Data!$A$2:$A$201,A9,Sales_Data!$E$2:$E$201) -> 6549.55 | G9: 312.91 | H9: 1317.53 | J9: Standard Error | K9: 86.281231 | V9: =Sales_Data!E8 -> 1317.53 | W9: =Sales_Data!I8 -> 312.91 | Y9: =EDATE(Y8,1) -> 45566 | Z9: =SUMIFS(Sales_Data!$E$2:$E$201,Sales_Data!$H$2:$H$201,">="&Y9,Sales_Data!$H$2:$H$201,"<"&EDATE(Y9,1)) -> 14215.24 | AA9: =IFERROR((Z9-Z8)/Z8,0) -> -0.30770497 | AC9: Mary Davis | AD9: =SUMIF(Sales_Data!$B$2:$B$201,AC8,Sales_Data!$E$2:$E$201) -> 9970.2 | AF9: CUST007 | AG9: 9941.88
A10: CUST026 | B10: =SUMIF(Sales_Data!$A$2:$A$201,A10,Sales_Data!$E$2:$E$201) -> 9371.81 | G10: 300.85 | H10: 1074.47 | J10: Observations | K10: 200 | V10: =Sales_Data!E9 -> 1074.47 | W10: =Sales_Data!I9 -> 300.85 | Y10: =EDATE(Y9,1) -> 45597 | Z10: =SUMIFS(Sales_Data!$E$2:$E$201,Sales_Data!$H$2:$H$201,">="&Y10,Sales_Data!$H$2:$H$201,"<"&EDATE(Y10,1)) -> 20135.03 | AA10: =IFERROR((Z10-Z9)/Z9,0) -> 0.41643968 | AC10: Linda Jackson | AD10: =SUMIF(Sales_Data!$B$2:$B$201,AC9,Sales_Data!$E$2:$E$201) -> 17143.29 | AF10: CUST008 | AG10: 9760.8
A11: CUST009 | B11: =SUMIF(Sales_Data!$A$2:$A$201,A11,Sales_Data!$E$2:$E$201) -> 6505.2 | G11: 190.59 | H11: 501.54 | V11: =Sales_Data!E10 -> 501.54 | W11: =Sales_Data!I10 -> 190.59 | Y11: =EDATE(Y10,1) -> 45627 | Z11: =SUMIFS(Sales_Data!$E$2:$E$201,Sales_Data!$H$2:$H$201,">="&Y11,Sales_Data!$H$2:$H$201,"<"&EDATE(Y11,1)) -> 11120.04 | AA11: =IFERROR((Z11-Z10)/Z10,0) -> -0.44772667 | AC11: David Thomas | AD11: =SUMIF(Sales_Data!$B$2:$B$201,AC10,Sales_Data!$E$2:$E$201) -> 3968.59 | AF11: CUST026 | AG11: 9371.81
A12: CUST010 | B12: =SUMIF(Sales_Data!$A$2:$A$201,A12,Sales_Data!$E$2:$E$201) -> 4259.22 | G12: 350.22 | H12: 737.31 | J12: ANOVA | V12: =Sales_Data!E11 -> 737.31 | W12: =Sales_Data!I11 -> 350.22 | Y12: =EDATE(Y11,1) -> 45658 | Z12: =SUMIFS(Sales_Data!$E$2:$E$201,Sales_Data!$H$2:$H$201,">="&Y12,Sales_Data!$H$2:$H$201,"<"&EDATE(Y12,1)) -> 14914.65 | AA12: =IFERROR((Z12-Z11)/Z11,0) -> 0.34124068 | AC12: Emma Davis | AD12: =SUMIF(Sales_Data!$B$2:$B$201,AC11,Sales_Data!$E$2:$E$201) -> 7020.38 | AF12: CUST007 | AG12: 9941.88
A13: CUST014 | B13: =SUMIF(Sales_Data!$A$2:$A$201,A13,Sales_Data!$E$2:$E$201) -> 6729.89 | G13: 672.38 | H13: 1572.82 | K13: df | L13: SS | M13: MS | N13: F | O13: Significance F | V13: =Sales_Data!E12 -> 1572.82 | W13: =Sales_Data!I12 -> 672.38 | Y13: =EDATE(Y12,1) -> 45689 | Z13: =SUMIFS(Sales_Data!$E$2:$E$201,Sales_Data!$H$2:$H$201,">="&Y13,Sales_Data!$H$2:$H$201,"<"&EDATE(Y13,1)) -> 14006.36 | AA13: =IFERROR((Z13-Z12)/Z12,0) -> -0.060899183 | AC13: David Smith | AD13: =SUMIF(Sales_Data!$B$2:$B$201,AC12,Sales_Data!$E$2:$E$201) -> 11398.32 | AF13: CUST012 | AG13: 8339
A14: CUST014 | B14: =SUMIF(Sales_Data!$A$2:$A$201,A14,Sales_Data!$E$2:$E$201) -> 6729.89 | G14: 456.66 | H14: 1343.13 | J14: Regression | K14: 1 | L14: 2194058.2 | M14: 2194058.2 | N14: 294.72398 | O14: 4.6269368e-41 | V14: =Sales_Data!E13 -> 1343.13 | W14: =Sales_Data!I13 -> 456.66 | Y14: =EDATE(Y13,1) -> 45717 | Z14: =SUMIFS(Sales_Data!$E$2:$E$201,Sales_Data!$H$2:$H$201,">="&Y14,Sales_Data!$H$2:$H$201,"<"&EDATE(Y14,1)) -> 17655.22 | AA14: =IFERROR((Z14-Z13)/Z13,0) -> 0.26051451 | AC14: Sarah Anderson | AD14: =SUMIF(Sales_Data!$B$2:$B$201,AC13,Sales_Data!$E$2:$E$201) -> 1672.88
A15: CUST007 | B15: =SUMIF(Sales_Data!$A$2:$A$201,A15,Sales_Data!$E$2:$E$201) -> 9941.88 | G15: 452.8 | H15: 1191.58 | J15: Residual | K15: 198 | L15: 1474001.2 | M15: 7444.4507 | V15: =Sales_Data!E14 -> 1191.58 | W15: =Sales_Data!I14 -> 452.8 | Y15: =EDATE(Y14,1) -> 45748 | Z15: =SUMIFS(Sales_Data!$E$2:$E$201,Sales_Data!$H$2:$H$201,">="&Y15,Sales_Data!$H$2:$H$201,"<"&EDATE(Y15,1)) -> 3212.17 | AA15: =IFERROR((Z15-Z14)/Z14,0) -> -0.81806117 | AC15: Lisa Thomas | AD15: =SUMIF(Sales_Data!$B$2:$B$201,AC14,Sales_Data!$E$2:$E$201) -> 7296.19
A16: CUST023 | B16: =SUMIF(Sales_Data!$A$2:$A$201,A16,Sales_Data!$E$2:$E$201) -> 5913.68 | G16: 273.41 | H16: 822.28 | J16: Total | K16: 199 | L16: 3668059.4 | V16: =Sales_Data!E15 -> 822.28 | W16: =Sales_Data!I15 -> 273.41 | AC16: Mary Jackson | AD16: =SUMIF(Sales_Data!$B$2:$B$201,AC15,Sales_Data!$E$2:$E$201) -> 8635.95
A17: CUST029 | B17: =SUMIF(Sales_Data!$A$2:$A$201,A17,Sales_Data!$E$2:$E$201) -> 5779.05 | G17: 155.2 | H17: 521.67 | V17: =Sales_Data!E16 -> 521.67 | W17: =Sales_Data!I16 -> 155.2 | AC17: Lisa Davis | AD17: =SUMIF(Sales_Data!$B$2:$B$201,AC16,Sales_Data!$E$2:$E$201) -> 7251.18
A18: CUST005 | B18: =SUMIF(Sales_Data!$A$2:$A$201,A18,Sales_Data!$E$2:$E$201) -> 6666.13 | G18: 300.59 | H18: 1502.93 | K18: Coefficients | L18: Standard Error | M18: t Stat | N18: P-value | O18: Lower 95% | P18: Upper 95% | Q18: Lower 95.0% | R18: Upper 95.0% | V18: =Sales_Data!E17 -> 1502.93 | W18: =Sales_Data!I17 -> 300.59 | AC18: Linda Brown | AD18: =SUMIF(Sales_Data!$B$2:$B$201,AC17,Sales_Data!$E$2:$E$201) -> 8090.12
A19: CUST008 | B19: =SUMIF(Sales_Data!$A$2:$A$201,A19,Sales_Data!$E$2:$E$201) -> 9760.8 | G19: 298.38 | H19: 877.58 | J19: Intercept | K19: -1.0315505 | L19: 20.860617 | M19: -0.049449663 | N19: 0.9606108 | O19: -42.169052 | P19: 40.105951 | Q19: -42.169052 | R19: 40.105951 | V19: =Sales_Data!E18 -> 877.58 | W19: =Sales_Data!I18 -> 298.38 | AC19: John Brown | AD19: =SUMIF(Sales_Data!$B$2:$B$201,AC18,Sales_Data!$E$2:$E$201) -> 5801.29
A20: CUST001 | B20: =SUMIF(Sales_Data!$A$2:$A$201,A20,Sales_Data!$E$2:$E$201) -> 6549.55 | G20: 203.74 | H20: 636.7 | J20: Sales | K20: 0.35085599 | L20: 0.020437189 | M20: 17.167527 | N20: 4.6269368e-41 | O20: 0.3105535 | P20: 0.39115848 | Q20: 0.3105535 | R20: 0.39115848 | V20: =Sales_Data!E19 -> 636.7 | W20: =Sales_Data!I19 -> 203.74 | AC20: Linda Taylor | AD20: =SUMIF(Sales_Data!$B$2:$B$201,AC19,Sales_Data!$E$2:$E$201) -> 1450.99
A21: CUST006 | B21: =SUMIF(Sales_Data!$A$2:$A$201,A21,Sales_Data!$E$2:$E$201) -> 2699.75 | G21: 481.96 | H21: 1506.14 | V21: =Sales_Data!E20 -> 1506.14 | W21: =Sales_Data!I20 -> 481.96 | AC21: David Brown | AD21: =SUMIF(Sales_Data!$B$2:$B$201,AC20,Sales_Data!$E$2:$E$201) -> 7522.77
A22: CUST026 | B22: =SUMIF(Sales_Data!$A$2:$A$201,A22,Sales_Data!$E$2:$E$201) -> 9371.81 | G22: 161.26 | H22: 645.02 | V22: =Sales_Data!E21 -> 645.02 | W22: =Sales_Data!I21 -> 161.26 | AC22: David Davis | AD22: =SUMIF(Sales_Data!$B$2:$B$201,AC21,Sales_Data!$E$2:$E$201) -> 11915.83
A23: CUST007 | B23: =SUMIF(Sales_Data!$A$2:$A$201,A23,Sales_Data!$E$2:$E$201) -> 9941.88 | G23: 476.65 | H23: 953.3 | V23: =Sales_Data!E22 -> 953.3 | W23: =Sales_Data!I22 -> 476.65 | AC23: Mary Wilson | AD23: =SUMIF(Sales_Data!$B$2:$B$201,AC22,Sales_Data!$E$2:$E$201) -> 3819.14
A24: CUST022 | B24: =SUMIF(Sales_Data!$A$2:$A$201,A24,Sales_Data!$E$2:$E$201) -> 4418.28 | G24: 82.57 | H24: 388.56 | J24: Descriptive Statistics | M24: Histogram — Sales Distribution | V24: =Sales_Data!E23 -> 388.56 | W24: =Sales_Data!I23 -> 82.57 | AC24: Emma Wilson | AD24: =SUMIF(Sales_Data!$B$2:$B$201,AC23,Sales_Data!$E$2:$E$201) -> 5443.34
A25: CUST019 | B25: =SUMIF(Sales_Data!$A$2:$A$201,A25,Sales_Data!$E$2:$E$201) -> 4640.11 | G25: 297.27 | H25: 743.17 | J25: Sales | M25: Bin | N25: Frequency | V25: =Sales_Data!E24 -> 743.17 | W25: =Sales_Data!I24 -> 297.27 | AC25: Linda Davis | AD25: =SUMIF(Sales_Data!$B$2:$B$201,AC24,Sales_Data!$E$2:$E$201) -> 8543.97
A26: CUST023 | B26: =SUMIF(Sales_Data!$A$2:$A$201,A26,Sales_Data!$E$2:$E$201) -> 5913.68 | G26: 176.59 | H26: 706.37 | M26: 258.51 | N26: 1 | V26: =Sales_Data!E25 -> 706.37 | W26: =Sales_Data!I25 -> 176.59 | AC26: Sarah Davis | AD26: =SUMIF(Sales_Data!$B$2:$B$201,AC25,Sales_Data!$E$2:$E$201) -> 856.7
A27: CUST012 | B27: =SUMIF(Sales_Data!$A$2:$A$201,A27,Sales_Data!$E$2:$E$201) -> 8339 | G27: 374.75 | H27: 925.31 | J27: Mean | K27: 976.32884 | M27: 377.44929 | N27: 2 | V27: =Sales_Data!E26 -> 925.31 | W27: =Sales_Data!I26 -> 374.75 | AC27: Emma Taylor | AD27: =SUMIF(Sales_Data!$B$2:$B$201,AC26,Sales_Data!$E$2:$E$201) -> 5771.59
A28: CUST010 | B28: =SUMIF(Sales_Data!$A$2:$A$201,A28,Sales_Data!$E$2:$E$201) -> 4259.22 | G28: 293.28 | H28: 1173.12 | J28: Standard Error | K28: 21.267092 | M28: 496.38857 | N28: 7 | V28: =Sales_Data!E27 -> 1173.12 | W28: =Sales_Data!I27 -> 293.28 | AC28: Linda Moore | AD28: =SUMIF(Sales_Data!$B$2:$B$201,AC27,Sales_Data!$E$2:$E$201) -> 5014.96
A29: CUST030 | B29: =SUMIF(Sales_Data!$A$2:$A$201,A29,Sales_Data!$E$2:$E$201) -> 7928.71 | G29: 236.44 | H29: 675.54 | J29: Median | K29: 980.18 | M29: 615.32786 | N29: 13 | V29: =Sales_Data!E28 -> 675.54 | W29: =Sales_Data!I28 -> 236.44 | AC29: David Anderson | AD29: =SUMIF(Sales_Data!$B$2:$B$201,AC28,Sales_Data!$E$2:$E$201) -> 2304.9
A30: CUST007 | B30: =SUMIF(Sales_Data!$A$2:$A$201,A30,Sales_Data!$E$2:$E$201) -> 9941.88 | G30: 356.85 | H30: 939.09 | J30: Mode | K30: #N/A | M30: 734.26714 | N30: 19 | V30: =Sales_Data!E29 -> 939.09 | W30: =Sales_Data!I29 -> 356.85
A31: CUST028 | B31: =SUMIF(Sales_Data!$A$2:$A$201,A31,Sales_Data!$E$2:$E$201) -> 10293.87 | G31: 398.25 | H31: 983.34 | J31: Standard Deviation | K31: 300.00925 | M31: 853.20643 | N31: 28 | V31: =Sales_Data!E30 -> 983.34 | W31: =Sales_Data!I30 -> 398.25
A32: CUST028 | B32: =SUMIF(Sales_Data!$A$2:$A$201,A32,Sales_Data!$E$2:$E$201) -> 10293.87 | G32: 160.24 | H32: 801.21 | J32: Sample Variance | K32: 90005.548 | M32: 972.14571 | N32: 29 | V32: =Sales_Data!E31 -> 801.21 | W32: =Sales_Data!I31 -> 160.24
G33: 326.41 | H33: 1450.71 | J33: Kurtosis | K33: -0.10296167 | M33: 1091.085 | N33: 31 | V33: =Sales_Data!E32 -> 1450.71 | W33: =Sales_Data!I32 -> 326.41
G34: 388.82 | H34: 1023.21 | J34: Skewness | K34: 0.14412008 | M34: 1210.0243 | N34: 28 | V34: =Sales_Data!E33 -> 1023.21 | W34: =Sales_Data!I33 -> 388.82
G35: 253.98 | H35: 853.72 | J35: Range | K35: 1665.15 | M35: 1328.9636 | N35: 17 | V35: =Sales_Data!E34 -> 853.72 | W35: =Sales_Data!I34 -> 253.98
G36: 217.78 | H36: 967.89 | J36: Minimum | K36: 258.51 | M36: 1447.9029 | N36: 11 | V36: =Sales_Data!E35 -> 967.89 | W36: =Sales_Data!I35 -> 217.78
G37: 513.38 | H37: 1200.9 | J37: Maximum | K37: 1923.66 | M37: 1566.8421 | N37: 8 | V37: =Sales_Data!E36 -> 1200.9 | W37: =Sales_Data!I36 -> 513.38
G38: 151.16 | H38: 472.38 | J38: Sum | K38: 194289.44 | M38: 1685.7814 | N38: 5 | V38: =Sales_Data!E37 -> 472.38 | W38: =Sales_Data!I37 -> 151.16
G39: 359.49 | H39: 840.92 | J39: Count | K39: 199 | M39: 1804.7207 | N39: 0 | V39: =Sales_Data!E38 -> 840.92 | W39: =Sales_Data!I38 -> 359.49
G40: 468.84 | H40: 1410.06 | M40: More | N40: 1 | V40: =Sales_Data!E39 -> 1410.06 | W40: =Sales_Data!I39 -> 468.84
...

Sheet Pivot
A1: Row Labels | B1: Sum of Sales
A2: Central | B2: 43468.33 | H2: Row Labels | I2: Sum of Sales
A3: East | B3: 32441.64 | H3: 2024 | I3: 145429.36
A4: North | B4: 34975.42 | H4: Qtr2 | I4: 57724.81
A5: South | B5: 40248.79 | H5: Qtr3 | I5: 42234.24
A6: West | B6: 44083.58 | H6: Qtr4 | I6: 45470.31
A7: Grand Total | B7: 195217.76 | H7: 2025 | I7: 49788.4
H8: Qtr1 | I8: 46576.23
H9: Qtr2 | I9: 3212.17
H10: Grand Total | I10: 195217.76

Sheet Sales_Data
A1: Customer_ID | B1: Customer_Name | C1: Region | D1: Product_Category | E1: Sales | F1: Quantity | G1: Discount | H1: Order_Date | I1: Profit | J1: Timestamp | L1: Discount | M1: Profit | N1: Adjusted Sales
A2: CUST019 | B2: James Davis | C2: West | D2: Books | E2: 1036.09 | F2: 4 | G2: 0.2 | H2: 45392 | I2: 331.55 | J2: =NOW() -> 46322.047 | L2: 0 | N2: =E2*(1-L2) -> 1036.09
A3: CUST012 | B3: Robert Anderson | C3: West | D3: Clothing | E3: 1101.28 | F3: 3 | G3: 0.2 | H3: 45393 | I3: 440.51 | L3: 0.05 | N3: =E2*(1-L3) -> 984.2855
A4: CUST017 | B4: James Taylor | C4: East | D4: Books | E4: 713.34 | F4: 17 | G4: 0 | H4: 45396 | I4: 285.34 | L4: 0.1 | N4: =E2*(1-L4) -> 932.481
A5: CUST005 | B5: Robert Anderson | C5: South | D5: Electronics | E5: 760.93 | F5: 4 | G5: 0.15 | H5: 45396 | I5: 161.7 | L5: 0.15 | N5: =E2*(1-L5) -> 880.6765
A6: CUST030 | B6: James Wilson | C6: North | D6: Books | E6: 847 | F6: 12 | G6: 0.2 | H6: 45397 | I6: 271.04 | L6: 0.2 | N6: =E2*(1-L6) -> 828.872
A7: CUST007 | B7: Michael Anderson | C7: North | D7: Furniture | E7: 965.64 | F7: 8 | G7: 0.1 | H7: 45398 | I7: 304.18
A8: CUST001 | B8: Linda Wilson | C8: West | D8: Electronics | E8: 1317.53 | F8: 12 | G8: 0.05 | H8: 45398 | I8: 312.91
A9: CUST026 | B9: Mary Davis | C9: East | D9: Furniture | E9: 1074.47 | F9: 6 | G9: 0.2 | H9: 45401 | I9: 300.85
A10: CUST009 | B10: Linda Jackson | C10: Central | D10: Books | E10: 501.54 | F10: 11 | G10: 0.05 | H10: 45401 | I10: 190.59
A11: CUST010 | B11: David Thomas | C11: Central | D11: Clothing | E11: 737.31 | F11: 2 | G11: 0.05 | H11: 45401 | I11: 350.22
A12: CUST014 | B12: Emma Davis | C12: West | D12: Office Supplies | E12: 1572.82 | F12: 6 | G12: 0.05 | H12: 45402 | I12: 672.38
A13: CUST014 | B13: David Thomas | C13: Central | D13: Books | E13: 1343.13 | F13: 14 | G13: 0.15 | H13: 45404 | I13: 456.66
A14: CUST007 | B14: Michael Anderson | C14: Central | D14: Books | E14: 1191.58 | F14: 14 | G14: 0.05 | H14: 45406 | I14: 452.8
A15: CUST023 | B15: Robert Anderson | C15: West | D15: Furniture | E15: 822.28 | F15: 7 | G15: 0.05 | H15: 45406 | I15: 273.41
A16: CUST029 | B16: David Smith | C16: North | D16: Furniture | E16: 521.67 | F16: 15 | G16: 0.15 | H16: 45409 | I16: 155.2
A17: CUST005 | B17: Sarah Anderson | C17: South | D17: Electronics | E17: 1502.93 | F17: 14 | G17: 0.2 | H17: 45410 | I17: 300.59
A18: CUST008 | B18: Robert Anderson | C18: South | D18: Books | E18: 877.58 | F18: 10 | G18: 0.15 | H18: 45411 | I18: 298.38
... A201: CUST016 | B201: David Thomas | C201: South | D201: Clothing | E201: 928.32 | F201: 2 | G201: 0.05 | H201: 45754 | I201: 440.95
E210: Cell લખવાનું H1 Discount I1 Profit H2 0% H3 5% H4 10% H5 15% H6 20%

Sheet Dashboard
A1: SALES ANALYSIS DASHBOARD
A2: Total Sales | B2: 195217.76 | D2: Pie Chart
H11: next
A20: Region | B20: Total Sales
A21: Central | B21: 43468.33
A22: East | B22: 32441.64
A23: North | B23: 34975.42
A24: South | B24: 40248.79
A25: West | B25: 44083.58
A26: Grand Total | B26: 195217.76

Sheet Data Storytelling
A1: Sales data story | C1: Analysis | D1: Result
C2: Total Sales | D2: 195217.76
C3: Highest Sales Region | D3: West
A4: Sales Analysis Insights | C4: Highest Region Sales | D4: 44083.58
C5: Lowest Sales Region | D5: East
A6: 1. Total Sales: The total sales across all regions are 195,217.76. | C6: Lowest Region Sales | D6: 32441
A8: 2. Best Performing Region: West has the highest sales, with 44,083.58.
A10: 3. Lowest Performing Region: East has the lowest sales, with 32,441.64.
A12: 4. Business Insight: The West and Central regions contribute strongly to overall sales. The East region may need further analysis to identify opportunities for improvement.
A14: 5. Conclusion: Comparing regional sales helps identify strong-performing regions and areas that may benefit from additional attention.
A16: 6. Regional Sales Comparison: The West region achieved the highest sales of 44,083.58, while the East region recorded the lowest sales of 32,441.64.
A18: have last step kayo che
A20: 8. Performance Difference: The difference between the highest-selling region (West) and the lowest-selling region (East) is 11,641.94.
A22: 9. Business Recommendation: The business should study the sales strategies used in the West and Central regions and explore ways to improve sales performance in the East region.
A24: 10. Final Conclusion: Regional sales analysis helps businesses understand performance differences, identify opportunities, and make better decisions using data.
